Traceback (most recent call last):
  File "C:\Users\ahelm\Desktop\project\LLM_automation\dynamic_correct.py", line 23, in try_run_pipeline
    exec(code_str, {})
  File "<string>", line 47, in <module>
  File "C:\Users\ahelm\AppData\Local\Programs\Python\Python310\lib\site-packages\pandas\io\parsers\readers.py", line 1026, in read_csv
    return _read(filepath_or_buffer, kwds)
  File "C:\Users\ahelm\AppData\Local\Programs\Python\Python310\lib\site-packages\pandas\io\parsers\readers.py", line 620, in _read
    parser = TextFileReader(filepath_or_buffer, **kwds)
  File "C:\Users\ahelm\AppData\Local\Programs\Python\Python310\lib\site-packages\pandas\io\parsers\readers.py", line 1620, in __init__
    self._engine = self._make_engine(f, self.engine)
  File "C:\Users\ahelm\AppData\Local\Programs\Python\Python310\lib\site-packages\pandas\io\parsers\readers.py", line 1880, in _make_engine
    self.handles = get_handle(
  File "C:\Users\ahelm\AppData\Local\Programs\Python\Python310\lib\site-packages\pandas\io\common.py", line 873, in get_handle
    handle = open(
FileNotFoundError: [Errno 2] No such file or directory: 'C:\\Users\\datasets\\adult_data\\adult_data.csv'
